Workbook

Sheet Dashboard
A1: Bahnpolitik im Deutschen Bundestag
A2: Auswertung der DIP-API des Deutschen Bundestages
N3: Typ | O3: Anzahl
A4: Drucksachen gesamt | B4: =COUNTA(Drucksachen!$D$2:$D$293) | N4: Kleine Anfrage | O4: =COUNTIF(Drucksachen!$E$2:$E$293,N4)
A5: davon Kleine Anfragen | B5: =COUNTIF(Drucksachen!$E$2:$E$293,"Kleine Anfrage") | N5: Antwort | O5: =COUNTIF(Drucksachen!$E$2:$E$293,N5)
A6: davon Antworten der Regierung | B6: =COUNTIF(Drucksachen!$E$2:$E$293,"Antwort") | N6: Antrag | O6: =COUNTIF(Drucksachen!$E$2:$E$293,N6)
A7: Antraege und Gesetzentwuerfe | B7: =COUNTIF(Drucksachen!$E$2:$E$293,"Antrag")+COUNTIF(Drucksachen!$E$2:$E$293,"Gesetzentwurf")+COUNTIF(Drucksachen!$E$2:$E$293,"Entschließungsantrag") | N7: Beschlussempfehlung und Bericht | O7: =COUNTIF(Drucksachen!$E$2:$E$293,N7)
A8: Initiativen der Opposition | B8: =COUNTIF(Drucksachen!$G$2:$G$293,"Opposition") | N8: Unterrichtung | O8: =COUNTIF(Drucksachen!$E$2:$E$293,N8)
A9: Initiativen der Regierungsfraktionen | B9: =COUNTIF(Drucksachen!$G$2:$G$293,"Regierungsfraktion") | N9: Wahlvorschlag | O9: =COUNTIF(Drucksachen!$E$2:$E$293,N9)
A10: Aktivste Fraktion | B10: =INDEX(Initiativen!$A$5:$A$9,MATCH(MAX(Initiativen!$G$5:$G$9),Initiativen!$G$5:$G$9,0)) | N10: Gesetzentwurf | O10: =COUNTIF(Drucksachen!$E$2:$E$293,N10)
A11: Mittlere Antwortzeit (Tage) | B11: =IFERROR(AVERAGEIFS(Drucksachen!$K$2:$K$293,Drucksachen!$K$2:$K$293,">0"),"") | N11: Ergänzende Antwort | O11: =COUNTIF(Drucksachen!$E$2:$E$293,N11)
A12: Erste Drucksache | B12: =MIN(Drucksachen!$A$2:$A$293) | N12: Entschließungsantrag | O12: =COUNTIF(Drucksachen!$E$2:$E$293,N12)
A13: Letzte Drucksache | B13: =MAX(Drucksachen!$A$2:$A$293)
N14: Rolle | O14: Anzahl
A15: Lesehinweise und Datenqualitaet | N15: Regierung | O15: =COUNTIF(Drucksachen!$G$2:$G$293,N15)
A16: • Erhebung ueber die Titelsuche der DIP-API. Eine Drucksache wird nur erfasst, wenn einer der Suchbegriffe im Titel steht - Vollstaendigkeit ist damit ausdruecklich nicht gegeben. | N16: Opposition | O16: =COUNTIF(Drucksachen!$G$2:$G$293,N16)
A17: • Suchbegriffe: Schienenverkehr, Schienennetz, Schieneninfrastruktur, Eisenbahn, Deutsche Bahn, Bahnstrecke, Bahnhof, Nahverkehr, Regionalisierungsmittel, Deutschlandtakt, Deutschlandticket | N17: Regierungsfraktion | O17: =COUNTIF(Drucksachen!$G$2:$G$293,N17)
A18: • Die Spalte 'Rolle ab WP 21' beschreibt den heutigen Status. Aeltere Drucksachen derselben Fraktion koennen aus der Oppositionszeit stammen - massgeblich ist die Spalte 'Rolle' auf dem Blatt Drucksachen. | N18: Ausschuss | O18: =COUNTIF(Drucksachen!$G$2:$G$293,N18)
A19: • Der Fraktionsvergleich auf dem Blatt 'Initiativen' zaehlt nur selbst eingebrachte Drucksachen. Antworten der Bundesregierung werden der Regierung zugerechnet, nicht der fragenden Fraktion. | N19: Fraktionsuebergreifend | O19: =COUNTIF(Drucksachen!$G$2:$G$293,N19)
A20: • Regierungsfraktionen stellen praktisch keine Kleinen Anfragen an die eigene Regierung. Hohe Zahlen bei Oppositionsfraktionen sind daher kein Mass fuer bahnpolitisches Engagement, sondern folgen aus der parlamentarischen Rolle. Die Spalte 'Rolle' macht das sichtbar. | N20: Sonstige | O20: =COUNTIF(Drucksachen!$G$2:$G$293,N20)
A21: • Wahlperiode 20 (bis Maerz 2025): Regierung aus SPD, Gruenen und FDP. Wahlperiode 21: Regierung aus CDU/CSU und SPD.
A22: • Gemeinschafts-Drucksachen mehrerer Fraktionen laufen unter 'Mehrere Fraktionen' und werden keiner einzelnen Fraktion zugerechnet.
A23: • Themen werden aus dem Titel abgeleitet, Mehrfachzuordnung ist moeglich und beabsichtigt.
A24: • Erstellt am 11.10.2026 10:58 durch bahnpolitik_dip.py Version 3.

Sheet Drucksachen
A1: Datum | B1: Jahr | C1: Quartal | D1: Nummer | E1: Typ | F1: Urheber | G1: Rolle | H1: WP | I1: Themen | J1: Bezug auf | K1: Antwort nach (Tage) | L1: Antwort in | M1: Titel | N1: Urheber (roh) | O1: PDF | P1: Anfrage von | Q1: Serie | R1: Abgestimmt
A2: 46294 | B2: =IF(A2="","",YEAR(A2)) | C2: =IF(A2="","",YEAR(A2)&"-Q"&ROUNDUP(MONTH(A2)/3,0)) | D2: 21/8263 | E2: Antwort | F2: Bundesregierung | G2: Regierung | H2: 21 | I2: Infrastruktur/Netz | J2: 21/7722 | K2: =IF(OR(J2="",LEFT(E2,7)<>"Antwort"),"",IFERROR(A2-INDEX($A$2:$A$293,MATCH(J2,$D$2:$D$293,0)),"")) | L2: =IF(E2<>"Kleine Anfrage","",IFERROR(INDEX($D$2:$D$293,MATCH(D2,$J$2:$J$293,0)),"offen")) | M2: Schieneninfrastruktur in Ostdeutschland | N2: Bundesregierung | O2: PDF | P2: Linke | R2: =IF(COUNTIF(Abstimmungen!$B$5:$B$2000,D2)-COUNTIFS(Abstimmungen!$B$5:$B$2000,D2,Abstimmungen!$D$5:$D$2000,"*berweisung*")>0,1,0)
A3: 46290 | B3: =IF(A3="","",YEAR(A3)) | C3: =IF(A3="","",YEAR(A3)&"-Q"&ROUNDUP(MONTH(A3)/3,0)) | D3: 21/8225 | E3: Kleine Anfrage | F3: AfD | G3: Opposition | H3: 21 | I3: Bahnhoefe; Kriminalitaet | K3: =IF(OR(J3="",LEFT(E3,7)<>"Antwort"),"",IFERROR(A3-INDEX($A$2:$A$293,MATCH(J3,$D$2:$D$293,0)),"")) | L3: =IF(E3<>"Kleine Anfrage","",IFERROR(INDEX($D$2:$D$293,MATCH(D3,$J$2:$J$293,0)),"offen")) | M3: Kriminalitätsfelder in Bezug auf Bahnhöfe und Züge im ersten Halbjahr 2026 | N3: Fraktion der AfD | O3: PDF | Q3: Bahnhöfe / Kriminalitätsfelder | R3: =IF(COUNTIF(Abstimmungen!$B$5:$B$2000,D3)-COUNTIFS(Abstimmungen!$B$5:$B$2000,D3,Abstimmungen!$D$5:$D$2000,"*berweisung*")>0,1,0)
A4: 46275 | B4: =IF(A4="","",YEAR(A4)) | C4: =IF(A4="","",YEAR(A4)&"-Q"&ROUNDUP(MONTH(A4)/3,0)) | D4: 21/7988 | E4: Antwort | F4: Bundesregierung | G4: Regierung | H4: 21 | I4: Puenktlichkeit/Qualitaet | J4: 21/7607 | K4: =IF(OR(J4="",LEFT(E4,7)<>"Antwort"),"",IFERROR(A4-INDEX($A$2:$A$293,MATCH(J4,$D$2:$D$293,0)),"")) | L4: =IF(E4<>"Kleine Anfrage","",IFERROR(INDEX($D$2:$D$293,MATCH(D4,$J$2:$J$293,0)),"offen")) | M4: Bundesweiter Funkausfall bei der Deutschen Bahn - Ursachen, Auswirkungen und Konsequenzen für die digitale Bahninfrastruktur | N4: Bundesregierung | O4: PDF | P4: AfD | R4: =IF(COUNTIF(Abstimmungen!$B$5:$B$2000,D4)-COUNTIFS(Abstimmungen!$B$5:$B$2000,D4,Abstimmungen!$D$5:$D$2000,"*berweisung*")>0,1,0)
A5: 46275 | B5: =IF(A5="","",YEAR(A5)) | C5: =IF(A5="","",YEAR(A5)&"-Q"&ROUNDUP(MONTH(A5)/3,0)) | D5: 21/8000 | E5: Unterrichtung | F5: Bundesregierung | G5: Regierung | H5: 21 | I5: Nahverkehr/SPNV; Finanzierung | K5: =IF(OR(J5="",LEFT(E5,7)<>"Antwort"),"",IFERROR(A5-INDEX($A$2:$A$293,MATCH(J5,$D$2:$D$293,0)),"")) | L5: =IF(E5<>"Kleine Anfrage","",IFERROR(INDEX($D$2:$D$293,MATCH(D5,$J$2:$J$293,0)),"offen")) | M5: Bericht der Bundesregierung zur Verwendung der Regionalisierungsmittel durch die Länder im Jahr 2020 | N5: Bundesregierung | O5: PDF | R5: =IF(COUNTIF(Abstimmungen!$B$5:$B$2000,D5)-COUNTIFS(Abstimmungen!$B$5:$B$2000,D5,Abstimmungen!$D$5:$D$2000,"*berweisung*")>0,1,0)
A6: 46268 | B6: =IF(A6="","",YEAR(A6)) | C6: =IF(A6="","",YEAR(A6)&"-Q"&ROUNDUP(MONTH(A6)/3,0)) | D6: 21/7838 | E6: Antwort | F6: Bundesregierung | G6: Regierung | H6: 21 | I6: Infrastruktur/Netz | J6: 21/7483 | K6: =IF(OR(J6="",LEFT(E6,7)<>"Antwort"),"",IFERROR(A6-INDEX($A$2:$A$293,MATCH(J6,$D$2:$D$293,0)),"")) | L6: =IF(E6<>"Kleine Anfrage","",IFERROR(INDEX($D$2:$D$293,MATCH(D6,$J$2:$J$293,0)),"offen")) | M6: Ersatz von Brücken auf der Bahnstrecke Köln-Siegen (Siegstrecke) | N6: Bundesregierung | O6: PDF | P6: Gruene | R6: =IF(COUNTIF(Abstimmungen!$B$5:$B$2000,D6)-COUNTIFS(Abstimmungen!$B$5:$B$2000,D6,Abstimmungen!$D$5:$D$2000,"*berweisung*")>0,1,0)
A7: 46261 | B7: =IF(A7="","",YEAR(A7)) | C7: =IF(A7="","",YEAR(A7)&"-Q"&ROUNDUP(MONTH(A7)/3,0)) | D7: 21/7755 | E7: Antwort | F7: Bundesregierung | G7: Regierung | H7: 21 | I7: Bahnhoefe | J7: 21/7468 | K7: =IF(OR(J7="",LEFT(E7,7)<>"Antwort"),"",IFERROR(A7-INDEX($A$2:$A$293,MATCH(J7,$D$2:$D$293,0)),"")) | L7: =IF(E7<>"Kleine Anfrage","",IFERROR(INDEX($D$2:$D$293,MATCH(D7,$J$2:$J$293,0)),"offen")) | M7: Anbindung des zukünftigen Abstellbahnhofs Untertürkheim an den Bahnhof Stuttgart-Bad Cannstatt | N7: Bundesregierung | O7: PDF | P7: Gruene | R7: =IF(COUNTIF(Abstimmungen!$B$5:$B$2000,D7)-COUNTIFS(Abstimmungen!$B$5:$B$2000,D7,Abstimmungen!$D$5:$D$2000,"*berweisung*")>0,1,0)
A8: 46259 | B8: =IF(A8="","",YEAR(A8)) | C8: =IF(A8="","",YEAR(A8)&"-Q"&ROUNDUP(MONTH(A8)/3,0)) | D8: 21/7722 | E8: Kleine Anfrage | F8: Linke | G8: Opposition | H8: 21 | I8: Infrastruktur/Netz | K8: =IF(OR(J8="",LEFT(E8,7)<>"Antwort"),"",IFERROR(A8-INDEX($A$2:$A$293,MATCH(J8,$D$2:$D$293,0)),"")) | L8: =IF(E8<>"Kleine Anfrage","",IFERROR(INDEX($D$2:$D$293,MATCH(D8,$J$2:$J$293,0)),"offen")) | M8: Schieneninfrastruktur in Ostdeutschland | N8: Fraktion DIE LINKE | O8: PDF | R8: =IF(COUNTIF(Abstimmungen!$B$5:$B$2000,D8)-COUNTIFS(Abstimmungen!$B$5:$B$2000,D8,Abstimmungen!$D$5:$D$2000,"*berweisung*")>0,1,0)
A9: 46251 | B9: =IF(A9="","",YEAR(A9)) | C9: =IF(A9="","",YEAR(A9)&"-Q"&ROUNDUP(MONTH(A9)/3,0)) | D9: 21/7607 | E9: Kleine Anfrage | F9: AfD | G9: Opposition | H9: 21 | I9: Puenktlichkeit/Qualitaet | K9: =IF(OR(J9="",LEFT(E9,7)<>"Antwort"),"",IFERROR(A9-INDEX($A$2:$A$293,MATCH(J9,$D$2:$D$293,0)),"")) | L9: =IF(E9<>"Kleine Anfrage","",IFERROR(INDEX($D$2:$D$293,MATCH(D9,$J$2:$J$293,0)),"offen")) | M9: Bundesweiter Funkausfall bei der Deutschen Bahn - Ursachen, Auswirkungen und Konsequenzen für die digitale Bahninfrastruktur | N9: Fraktion der AfD | O9: PDF | R9: =IF(COUNTIF(Abstimmungen!$B$5:$B$2000,D9)-COUNTIFS(Abstimmungen!$B$5:$B$2000,D9,Abstimmungen!$D$5:$D$2000,"*berweisung*")>0,1,0)
A10: 46239 | B10: =IF(A10="","",YEAR(A10)) | C10: =IF(A10="","",YEAR(A10)&"-Q"&ROUNDUP(MONTH(A10)/3,0)) | D10: 21/7483 | E10: Kleine Anfrage | F10: Gruene | G10: Opposition | H10: 21 | I10: Infrastruktur/Netz | K10: =IF(OR(J10="",LEFT(E10,7)<>"Antwort"),"",IFERROR(A10-INDEX($A$2:$A$293,MATCH(J10,$D$2:$D$293,0)),"")) | L10: =IF(E10<>"Kleine Anfrage","",IFERROR(INDEX($D$2:$D$293,MATCH(D10,$J$2:$J$293,0)),"offen")) | M10: Ersatz von Brücken auf der Bahnstrecke Köln-Siegen (Siegstrecke) | N10: Fraktion BÜNDNIS 90/DIE GRÜNEN | O10: PDF | R10: =IF(COUNTIF(Abstimmungen!$B$5:$B$2000,D10)-COUNTIFS(Abstimmungen!$B$5:$B$2000,D10,Abstimmungen!$D$5:$D$2000,"*berweisung*")>0,1,0)
A11: 46238 | B11: =IF(A11="","",YEAR(A11)) | C11: =IF(A11="","",YEAR(A11)&"-Q"&ROUNDUP(MONTH(A11)/3,0)) | D11: 21/7468 | E11: Kleine Anfrage | F11: Gruene | G11: Opposition | H11: 21 | I11: Bahnhoefe | K11: =IF(OR(J11="",LEFT(E11,7)<>"Antwort"),"",IFERROR(A11-INDEX($A$2:$A$293,MATCH(J11,$D$2:$D$293,0)),"")) | L11: =IF(E11<>"Kleine Anfrage","",IFERROR(INDEX($D$2:$D$293,MATCH(D11,$J$2:$J$293,0)),"offen")) | M11: Anbindung des zukünftigen Abstellbahnhofs Untertürkheim an den Bahnhof Stuttgart-Bad Cannstatt | N11: Fraktion BÜNDNIS 90/DIE GRÜNEN | O11: PDF | R11: =IF(COUNTIF(Abstimmungen!$B$5:$B$2000,D11)-COUNTIFS(Abstimmungen!$B$5:$B$2000,D11,Abstimmungen!$D$5:$D$2000,"*berweisung*")>0,1,0)
A12: 46225 | B12: =IF(A12="","",YEAR(A12)) | C12: =IF(A12="","",YEAR(A12)&"-Q"&ROUNDUP(MONTH(A12)/3,0)) | D12: 21/7277 | E12: Antwort | F12: Bundesregierung | G12: Regierung | H12: 21 | I12: Sicherheit | J12: 21/6626 | K12: =IF(OR(J12="",LEFT(E12,7)<>"Antwort"),"",IFERROR(A12-INDEX($A$2:$A$293,MATCH(J12,$D$2:$D$293,0)),"")) | L12: =IF(E12<>"Kleine Anfrage","",IFERROR(INDEX($D$2:$D$293,MATCH(D12,$J$2:$J$293,0)),"offen")) | M12: Risse von Oberleitungen der Deutschen Bahn AG im Jahr 2026, Gefährdungen von Fahrgästen und Krisenmanagement | N12: Bundesregierung | O12: PDF | P12: AfD | R12: =IF(COUNTIF(Abstimmungen!$B$5:$B$2000,D12)-COUNTIFS(Abstimmungen!$B$5:$B$2000,D12,Abstimmungen!$D$5:$D$2000,"*berweisung*")>0,1,0)
A13: 46210 | B13: =IF(A13="","",YEAR(A13)) | C13: =IF(A13="","",YEAR(A13)&"-Q"&ROUNDUP(MONTH(A13)/3,0)) | D13: 21/6922 | E13: Antrag | F13: Gruene | G13: Opposition | H13: 21 | I13: Infrastruktur/Netz; Konzernstruktur/DB AG | K13: =IF(OR(J13="",LEFT(E13,7)<>"Antwort"),"",IFERROR(A13-INDEX($A$2:$A$293,MATCH(J13,$D$2:$D$293,0)),"")) | L13: =IF(E13<>"Kleine Anfrage","",IFERROR(INDEX($D$2:$D$293,MATCH(D13,$J$2:$J$293,0)),"offen")) | M13: Stillstand in der Bahnpolitik überwinden - Strukturreformen umsetzen, Kapazitäten des Schienennetzes verstärken und ein gutes Fernverkehrsangebot sicherstellen | N13: Fraktion BÜNDNIS 90/DIE GRÜNEN | O13: PDF | R13: =IF(COUNTIF(Abstimmungen!$B$5:$B$2000,D13)-COUNTIFS(Abstimmungen!$B$5:$B$2000,D13,Abstimmungen!$D$5:$D$2000,"*berweisung*")>0,1,0)
A14: 46209 | B14: =IF(A14="","",YEAR(A14)) | C14: =IF(A14="","",YEAR(A14)&"-Q"&ROUNDUP(MONTH(A14)/3,0)) | D14: 21/6880 | E14: Beschlussempfehlung und Bericht | F14: Verkehrsausschuss | G14: Ausschuss | H14: 21 | I14: Konzernstruktur/DB AG | J14: 21/6331 | K14: =IF(OR(J14="",LEFT(E14,7)<>"Antwort"),"",IFERROR(A14-INDEX($A$2:$A$293,MATCH(J14,$D$2:$D$293,0)),"")) | L14: =IF(E14<>"Kleine Anfrage","",IFERROR(INDEX($D$2:$D$293,MATCH(D14,$J$2:$J$293,0)),"offen")) | M14: Leistung erbringen, Neutralität wahren - Aufgabenfremde Maßnahmen wie die Regenbogenbeflaggung bei der Deutsche Bahn AG unterlassen | N14: Verkehrsausschuss | O14: PDF | R14: =IF(COUNTIF(Abstimmungen!$B$5:$B$2000,D14)-COUNTIFS(Abstimmungen!$B$5:$B$2000,D14,Abstimmungen!$D$5:$D$2000,"*berweisung*")>0,1,0)
A15: 46204 | B15: =IF(A15="","",YEAR(A15)) | C15: =IF(A15="","",YEAR(A15)&"-Q"&ROUNDUP(MONTH(A15)/3,0)) | D15: 21/6812 | E15: Antwort | F15: Bundesregierung | G15: Regierung | H15: 21 | I15: Infrastruktur/Netz | J15: 21/6517 | K15: =IF(OR(J15="",LEFT(E15,7)<>"Antwort"),"",IFERROR(A15-INDEX($A$2:$A$293,MATCH(J15,$D$2:$D$293,0)),"")) | L15: =IF(E15<>"Kleine Anfrage","",IFERROR(INDEX($D$2:$D$293,MATCH(D15,$J$2:$J$293,0)),"offen")) | M15: Ausbau der Bahnstrecke Berlin-Dresden und mögliche Reduzierung auf 160 km/h | N15: Bundesregierung | O15: PDF | P15: Linke | R15: =IF(COUNTIF(Abstimmungen!$B$5:$B$2000,D15)-COUNTIFS(Abstimmungen!$B$5:$B$2000,D15,Abstimmungen!$D$5:$D$2000,"*berweisung*")>0,1,0)
A16: 46197 | B16: =IF(A16="","",YEAR(A16)) | C16: =IF(A16="","",YEAR(A16)&"-Q"&ROUNDUP(MONTH(A16)/3,0)) | D16: 21/6701 | E16: Beschlussempfehlung und Bericht | F16: Verkehrsausschuss | G16: Ausschuss | H16: 21 | I16: Infrastruktur/Netz | J16: 21/4099 | K16: =IF(OR(J16="",LEFT(E16,7)<>"Antwort"),"",IFERROR(A16-INDEX($A$2:$A$293,MATCH(J16,$D$2:$D$293,0)),"")) | L16: =IF(E16<>"Kleine Anfrage","",IFERROR(INDEX($D$2:$D$293,MATCH(D16,$J$2:$J$293,0)),"offen")) | M16: Entwurf eines Infrastruktur-Zukunftsgesetzes | N16: Verkehrsausschuss | O16: PDF | R16: =IF(COUNTIF(Abstimmungen!$B$5:$B$2000,D16)-COUNTIFS(Abstimmungen!$B$5:$B$2000,D16,Abstimmungen!$D$5:$D$2000,"*berweisung*")>0,1,0)
A17: 46197 | B17: =IF(A17="","",YEAR(A17)) | C17: =IF(A17="","",YEAR(A17)&"-Q"&ROUNDUP(MONTH(A17)/3,0)) | D17: 21/6626 | E17: Kleine Anfrage | F17: AfD | G17: Opposition | H17: 21 | I17: Sicherheit | K17: =IF(OR(J17="",LEFT(E17,7)<>"Antwort"),"",IFERROR(A17-INDEX($A$2:$A$293,MATCH(J17,$D$2:$D$293,0)),"")) | L17: =IF(E17<>"Kleine Anfrage","",IFERROR(INDEX($D$2:$D$293,MATCH(D17,$J$2:$J$293,0)),"offen")) | M17: Risse von Oberleitungen der Deutschen Bahn AG im Jahr 2026, Gefährdungen von Fahrgästen und Krisenmanagement | N17: Fraktion der AfD | O17: PDF | R17: =IF(COUNTIF(Abstimmungen!$B$5:$B$2000,D17)-COUNTIFS(Abstimmungen!$B$5:$B$2000,D17,Abstimmungen!$D$5:$D$2000,"*berweisung*")>0,1,0)
A18: 46195 | B18: =IF(A18="","",YEAR(A18)) | C18: =IF(A18="","",YEAR(A18)&"-Q"&ROUNDUP(MONTH(A18)/3,0)) | D18: 21/6601 | E18: Antwort | F18: Bundesregierung | G18: Regierung | H18: 21 | I18: Bahnhoefe; Kriminalitaet; Sicherheit | J18: 21/6208 | K18: =IF(OR(J18="",LEFT(E18,7)<>"Antwort"),"",IFERROR(A18-INDEX($A$2:$A$293,MATCH(J18,$D$2:$D$293,0)),"")) | L18: =IF(E18<>"Kleine Anfrage","",IFERROR(INDEX($D$2:$D$293,MATCH(D18,$J$2:$J$293,0)),"offen")) | M18: Sicherheit an Bahnhöfen in Bayern - Entwicklung von Sachbeschädigungs-, Körperverletzungs-, Diebstahls- und Raubdelikten sowie Maßnahmen der Bundespolizei | N18: Bundesregierung | O18: PDF | P18: AfD | R18: =IF(COUNTIF(Abstimmungen!$B$5:$B$2000,D18)-COUNTIFS(Abstimmungen!$B$5:$B$2000,D18,Abstimmungen!$D$5:$D$2000,"*berweisung*")>0,1,0)
A19: 46189 | B19: =IF(A19="","",YEAR(A19)) | C19: =IF(A19="","",YEAR(A19)&"-Q"&ROUNDUP(MONTH(A19)/3,0)) | D19: 21/6517 | E19: Kleine Anfrage | F19: Linke | G19: Opposition | H19: 21 | I19: Infrastruktur/Netz | K19: =IF(OR(J19="",LEFT(E19,7)<>"Antwort"),"",IFERROR(A19-INDEX($A$2:$A$293,MATCH(J19,$D$2:$D$293,0)),"")) | L19: =IF(E19<>"Kleine Anfrage","",IFERROR(INDEX($D$2:$D$293,MATCH(D19,$J$2:$J$293,0)),"offen")) | M19: Ausbau der Bahnstrecke Berlin-Dresden und mögliche Reduzierung auf 160 km/h | N19: Fraktion DIE LINKE | O19: PDF | R19: =IF(COUNTIF(Abstimmungen!$B$5:$B$2000,D19)-COUNTIFS(Abstimmungen!$B$5:$B$2000,D19,Abstimmungen!$D$5:$D$2000,"*berweisung*")>0,1,0)
A20: 46182 | B20: =IF(A20="","",YEAR(A20)) | C20: =IF(A20="","",YEAR(A20)&"-Q"&ROUNDUP(MONTH(A20)/3,0)) | D20: 21/6331 | E20: Antrag | F20: AfD | G20: Opposition | H20: 21 | I20: Konzernstruktur/DB AG | K20: =IF(OR(J20="",LEFT(E20,7)<>"Antwort"),"",IFERROR(A20-INDEX($A$2:$A$293,MATCH(J20,$D$2:$D$293,0)),"")) | L20: =IF(E20<>"Kleine Anfrage","",IFERROR(INDEX($D$2:$D$293,MATCH(D20,$J$2:$J$293,0)),"offen")) | M20: Leistung erbringen, Neutralität wahren - Aufgabenfremde Maßnahmen wie die Regenbogenbeflaggung bei der Deutsche Bahn AG unterlassen | N20: Fraktion der AfD | O20: PDF | R20: =IF(COUNTIF(Abstimmungen!$B$5:$B$2000,D20)-COUNTIFS(Abstimmungen!$B$5:$B$2000,D20,Abstimmungen!$D$5:$D$2000,"*berweisung*")>0,1,0)
A21: 46175 | B21: =IF(A21="","",YEAR(A21)) | C21: =IF(A21="","",YEAR(A21)&"-Q"&ROUNDUP(MONTH(A21)/3,0)) | D21: 21/6208 | E21: Kleine Anfrage | F21: AfD | G21: Opposition | H21: 21 | I21: Bahnhoefe; Kriminalitaet; Sicherheit | K21: =IF(OR(J21="",LEFT(E21,7)<>"Antwort"),"",IFERROR(A21-INDEX($A$2:$A$293,MATCH(J21,$D$2:$D$293,0)),"")) | L21: =IF(E21<>"Kleine Anfrage","",IFERROR(INDEX($D$2:$D$293,MATCH(D21,$J$2:$J$293,0)),"offen")) | M21: Sicherheit an Bahnhöfen in Bayern - Entwicklung von Sachbeschädigungs-, Körperverletzungs-, Diebstahls- und Raubdelikten sowie Maßnahmen der Bundespolizei | N21: Fraktion der AfD | O21: PDF | R21: =IF(COUNTIF(Abstimmungen!$B$5:$B$2000,D21)-COUNTIFS(Abstimmungen!$B$5:$B$2000,D21,Abstimmungen!$D$5:$D$2000,"*berweisung*")>0,1,0)
A22: 46168 | B22: =IF(A22="","",YEAR(A22)) | C22: =IF(A22="","",YEAR(A22)&"-Q"&ROUNDUP(MONTH(A22)/3,0)) | D22: 21/6188 | E22: Antwort | F22: Bundesregierung | G22: Regierung | H22: 21 | I22: Bahnhoefe; Kriminalitaet | J22: 21/5940 | K22: =IF(OR(J22="",LEFT(E22,7)<>"Antwort"),"",IFERROR(A22-INDEX($A$2:$A$293,MATCH(J22,$D$2:$D$293,0)),"")) | L22: =IF(E22<>"Kleine Anfrage","",IFERROR(INDEX($D$2:$D$293,MATCH(D22,$J$2:$J$293,0)),"offen")) | M22: Entwicklung der Kriminalität im Bereich des Bahnhofs der Stadt Detmold im Jahr 2025 | N22: Bundesregierung | O22: PDF | P22: AfD | R22: =IF(COUNTIF(Abstimmungen!$B$5:$B$2000,D22)-COUNTIFS(Abstimmungen!$B$5:$B$2000,D22,Abstimmungen!$D$5:$D$2000,"*berweisung*")>0,1,0)
A23: 46168 | B23: =IF(A23="","",YEAR(A23)) | C23: =IF(A23="","",YEAR(A23)&"-Q"&ROUNDUP(MONTH(A23)/3,0)) | D23: 21/6187 | E23: Antwort | F23: Bundesregierung | G23: Regierung | H23: 21 | I23: Bahnhoefe; Kriminalitaet | J23: 21/5938 | K23: =IF(OR(J23="",LEFT(E23,7)<>"Antwort"),"",IFERROR(A23-INDEX($A$2:$A$293,MATCH(J23,$D$2:$D$293,0)),"")) | L23: =IF(E23<>"Kleine Anfrage","",IFERROR(INDEX($D$2:$D$293,MATCH(D23,$J$2:$J$293,0)),"offen")) | M23: Entwicklung der Kriminalität im Bereich des Bahnhofs der Stadt Herford im Jahr 2025 | N23: Bundesregierung | O23: PDF | P23: AfD | R23: =IF(COUNTIF(Abstimmungen!$B$5:$B$2000,D23)-COUNTIFS(Abstimmungen!$B$5:$B$2000,D23,Abstimmungen!$D$5:$D$2000,"*berweisung*")>0,1,0)
A24: 46168 | B24: =IF(A24="","",YEAR(A24)) | C24: =IF(A24="","",YEAR(A24)&"-Q"&ROUNDUP(MONTH(A24)/3,0)) | D24: 21/6186 | E24: Antwort | F24: Bundesregierung | G24: Regierung | H24: 21 | I24: Bahnhoefe; Kriminalitaet | J24: 21/5941 | K24: =IF(OR(J24="",LEFT(E24,7)<>"Antwort"),"",IFERROR(A24-INDEX($A$2:$A$293,MATCH(J24,$D$2:$D$293,0)),"")) | L24: =IF(E24<>"Kleine Anfrage","",IFERROR(INDEX($D$2:$D$293,MATCH(D24,$J$2:$J$293,0)),"offen")) | M24: Entwicklung der Kriminalität im Bereich des Bahnhofs der Stadt Lage im Jahr 2025 | N24: Bundesregierung | O24: PDF | P24: AfD | R24: =IF(COUNTIF(Abstimmungen!$B$5:$B$2000,D24)-COUNTIFS(Abstimmungen!$B$5:$B$2000,D24,Abstimmungen!$D$5:$D$2000,"*berweisung*")>0,1,0)
A25: 46168 | B25: =IF(A25="","",YEAR(A25)) | C25: =IF(A25="","",YEAR(A25)&"-Q"&ROUNDUP(MONTH(A25)/3,0)) | D25: 21/6185 | E25: Antwort | F25: Bundesregierung | G25: Regierung | H25: 21 | I25: Bahnhoefe; Kriminalitaet | J25: 21/5943 | K25: =IF(OR(J25="",LEFT(E25,7)<>"Antwort"),"",IFERROR(A25-INDEX($A$2:$A$293,MATCH(J25,$D$2:$D$293,0)),"")) | L25: =IF(E25<>"Kleine Anfrage","",IFERROR(INDEX($D$2:$D$293,MATCH(D25,$J$2:$J$293,0)),"offen")) | M25: Entwicklung der Kriminalität im Bereich des Bahnhofs der Stadt Löhne im Jahr 2025 | N25: Bundesregierung | O25: PDF | P25: AfD | R25: =IF(COUNTIF(Abstimmungen!$B$5:$B$2000,D25)-COUNTIFS(Abstimmungen!$B$5:$B$2000,D25,Abstimmungen!$D$5:$D$2000,"*berweisung*")>0,1,0)
A26: 46168 | B26: =IF(A26="","",YEAR(A26)) | C26: =IF(A26="","",YEAR(A26)&"-Q"&ROUNDUP(MONTH(A26)/3,0)) | D26: 21/6184 | E26: Antwort | F26: Bundesregierung | G26: Regierung | H26: 21 | I26: Bahnhoefe; Kriminalitaet | J26: 21/5949 | K26: =IF(OR(J26="",LEFT(E26,7)<>"Antwort"),"",IFERROR(A26-INDEX($A$2:$A$293,MATCH(J26,$D$2:$D$293,0)),"")) | L26: =IF(E26<>"Kleine Anfrage","",IFERROR(INDEX($D$2:$D$293,MATCH(D26,$J$2:$J$293,0)),"offen")) | M26: Entwicklung der Kriminalität im Bereich des Bahnhofs der Stadt Bünde im Jahr 2025 | N26: Bundesregierung | O26: PDF | P26: AfD | R26: =IF(COUNTIF(Abstimmungen!$B$5:$B$2000,D26)-COUNTIFS(Abstimmungen!$B$5:$B$2000,D26,Abstimmungen!$D$5:$D$2000,"*berweisung*")>0,1,0)
A27: 46168 | B27: =IF(A27="","",YEAR(A27)) | C27: =IF(A27="","",YEAR(A27)&"-Q"&ROUNDUP(MONTH(A27)/3,0)) | D27: 21/6157 | E27: Antwort | F27: Bundesregierung | G27: Regierung | H27: 21 | I27: Bahnhoefe; Kriminalitaet | J27: 21/5945 | K27: =IF(OR(J27="",LEFT(E27,7)<>"Antwort"),"",IFERROR(A27-INDEX($A$2:$A$293,MATCH(J27,$D$2:$D$293,0)),"")) | L27: =IF(E27<>"Kleine Anfrage","",IFERROR(INDEX($D$2:$D$293,MATCH(D27,$J$2:$J$293,0)),"offen")) | M27: Entwicklung der Kriminalität im Bereich des Bahnhofs der Stadt Warburg im Jahr 2025 | N27: Bundesregierung | O27: PDF | P27: AfD | R27: =IF(COUNTIF(Abstimmungen!$B$5:$B$2000,D27)-COUNTIFS(Abstimmungen!$B$5:$B$2000,D27,Abstimmungen!$D$5:$D$2000,"*berweisung*")>0,1,0)
A28: 46168 | B28: =IF(A28="","",YEAR(A28)) | C28: =IF(A28="","",YEAR(A28)&"-Q"&ROUNDUP(MONTH(A28)/3,0)) | D28: 21/6156 | E28: Antwort | F28: Bundesregierung | G28: Regierung | H28: 21 | I28: Bahnhoefe; Kriminalitaet | J28: 21/5947 | K28: =IF(OR(J28="",LEFT(E28,7)<>"Antwort"),"",IFERROR(A28-INDEX($A$2:$A$293,MATCH(J28,$D$2:$D$293,0)),"")) | L28: =IF(E28<>"Kleine Anfrage","",IFERROR(INDEX($D$2:$D$293,MATCH(D28,$J$2:$J$293,0)),"offen")) | M28: Entwicklung der Kriminalität im Bereich des Bahnhofs der Stadt Bad Oeynhausen im Jahr 2025 | N28: Bundesregierung | O28: PDF | P28: AfD | R28: =IF(COUNTIF(Abstimmungen!$B$5:$B$2000,D28)-COUNTIFS(Abstimmungen!$B$5:$B$2000,D28,Abstimmungen!$D$5:$D$2000,"*berweisung*")>0,1,0)
A29: 46163 | B29: =IF(A29="","",YEAR(A29)) | C29: =IF(A29="","",YEAR(A29)&"-Q"&ROUNDUP(MONTH(A29)/3,0)) | D29: 21/6096 | E29: Antwort | F29: Bundesregierung | G29: Regierung | H29: 21 | I29: Infrastruktur/Netz | J29: 21/5610 | K29: =IF(OR(J29="",LEFT(E29,7)<>"Antwort"),"",IFERROR(A29-INDEX($A$2:$A$293,MATCH(J29,$D$2:$D$293,0)),"")) | L29: =IF(E29<>"Kleine Anfrage","",IFERROR(INDEX($D$2:$D$293,MATCH(D29,$J$2:$J$293,0)),"offen")) | M29: Infrastrukturzustandsnoten Schieneninfrastruktur in Berlin | N29: Bundesregierung | O29: PDF | P29: Gruene | R29: =IF(COUNTIF(Abstimmungen!$B$5:$B$2000,D29)-COUNTIFS(Abstimmungen!$B$5:$B$2000,D29,Abstimmungen!$D$5:$D$2000,"*berweisung*")>0,1,0)
A30: 46157 | B30: =IF(A30="","",YEAR(A30)) | C30: =IF(A30="","",YEAR(A30)&"-Q"&ROUNDUP(MONTH(A30)/3,0)) | D30: 21/5949 | E30: Kleine Anfrage | F30: AfD | G30: Opposition | H30: 21 | I30: Bahnhoefe; Kriminalitaet | K30: =IF(OR(J30="",LEFT(E30,7)<>"Antwort"),"",IFERROR(A30-INDEX($A$2:$A$293,MATCH(J30,$D$2:$D$293,0)),"")) | L30: =IF(E30<>"Kleine Anfrage","",IFERROR(INDEX($D$2:$D$293,MATCH(D30,$J$2:$J$293,0)),"offen")) | M30: Entwicklung der Kriminalität im Bereich des Bahnhofs der Stadt Bünde im Jahr 2025 | N30: Fraktion der AfD | O30: PDF | Q30: Entwicklung / Kriminalität | R30: =IF(COUNTIF(Abstimmungen!$B$5:$B$2000,D30)-COUNTIFS(Abstimmungen!$B$5:$B$2000,D30,Abstimmungen!$D$5:$D$2000,"*berweisung*")>0,1,0)
A31: 46157 | B31: =IF(A31="","",YEAR(A31)) | C31: =IF(A31="","",YEAR(A31)&"-Q"&ROUNDUP(MONTH(A31)/3,0)) | D31: 21/5947 | E31: Kleine Anfrage | F31: AfD | G31: Opposition | H31: 21 | I31: Bahnhoefe; Kriminalitaet | K31: =IF(OR(J31="",LEFT(E31,7)<>"Antwort"),"",IFERROR(A31-INDEX($A$2:$A$293,MATCH(J31,$D$2:$D$293,0)),"")) | L31: =IF(E31<>"Kleine Anfrage","",IFERROR(INDEX($D$2:$D$293,MATCH(D31,$J$2:$J$293,0)),"offen")) | M31: Entwicklung der Kriminalität im Bereich des Bahnhofs der Stadt Bad Oeynhausen im Jahr 2025 | N31: Fraktion der AfD | O31: PDF | Q31: Entwicklung / Kriminalität | R31: =IF(COUNTIF(Abstimmungen!$B$5:$B$2000,D31)-COUNTIFS(Abstimmungen!$B$5:$B$2000,D31,Abstimmungen!$D$5:$D$2000,"*berweisung*")>0,1,0)
A32: 46157 | B32: =IF(A32="","",YEAR(A32)) | C32: =IF(A32="","",YEAR(A32)&"-Q"&ROUNDUP(MONTH(A32)/3,0)) | D32: 21/5945 | E32: Kleine Anfrage | F32: AfD | G32: Opposition | H32: 21 | I32: Bahnhoefe; Kriminalitaet | K32: =IF(OR(J32="",LEFT(E32,7)<>"Antwort"),"",IFERROR(A32-INDEX($A$2:$A$293,MATCH(J32,$D$2:$D$293,0)),"")) | L32: =IF(E32<>"Kleine Anfrage","",IFERROR(INDEX($D$2:$D$293,MATCH(D32,$J$2:$J$293,0)),"offen")) | M32: Entwicklung der Kriminalität im Bereich des Bahnhofs der Stadt Warburg im Jahr 2025 | N32: Fraktion der AfD | O32: PDF | Q32: Entwicklung / Kriminalität | R32: =IF(COUNTIF(Abstimmungen!$B$5:$B$2000,D32)-COUNTIFS(Abstimmungen!$B$5:$B$2000,D32,Abstimmungen!$D$5:$D$2000,"*berweisung*")>0,1,0)
A33: 46157 | B33: =IF(A33="","",YEAR(A33)) | C33: =IF(A33="","",YEAR(A33)&"-Q"&ROUNDUP(MONTH(A33)/3,0)) | D33: 21/5943 | E33: Kleine Anfrage | F33: AfD | G33: Opposition | H33: 21 | I33: Bahnhoefe; Kriminalitaet | K33: =IF(OR(J33="",LEFT(E33,7)<>"Antwort"),"",IFERROR(A33-INDEX($A$2:$A$293,MATCH(J33,$D$2:$D$293,0)),"")) | L33: =IF(E33<>"Kleine Anfrage","",IFERROR(INDEX($D$2:$D$293,MATCH(D33,$J$2:$J$293,0)),"offen")) | M33: Entwicklung der Kriminalität im Bereich des Bahnhofs der Stadt Löhne im Jahr 2025 | N33: Fraktion der AfD | O33: PDF | Q33: Entwicklung / Kriminalität | R33: =IF(COUNTIF(Abstimmungen!$B$5:$B$2000,D33)-COUNTIFS(Abstimmungen!$B$5:$B$2000,D33,Abstimmungen!$D$5:$D$2000,"*berweisung*")>0,1,0)
A34: 46157 | B34: =IF(A34="","",YEAR(A34)) | C34: =IF(A34="","",YEAR(A34)&"-Q"&ROUNDUP(MONTH(A34)/3,0)) | D34: 21/5941 | E34: Kleine Anfrage | F34: AfD | G34: Opposition | H34: 21 | I34: Bahnhoefe; Kriminalitaet | K34: =IF(OR(J34="",LEFT(E34,7)<>"Antwort"),"",IFERROR(A34-INDEX($A$2:$A$293,MATCH(J34,$D$2:$D$293,0)),"")) | L34: =IF(E34<>"Kleine Anfrage","",IFERROR(INDEX($D$2:$D$293,MATCH(D34,$J$2:$J$293,0)),"offen")) | M34: Entwicklung der Kriminalität im Bereich des Bahnhofs der Stadt Lage im Jahr 2025 | N34: Fraktion der AfD | O34: PDF | Q34: Entwicklung / Kriminalität | R34: =IF(COUNTIF(Abstimmungen!$B$5:$B$2000,D34)-COUNTIFS(Abstimmungen!$B$5:$B$2000,D34,Abstimmungen!$D$5:$D$2000,"*berweisung*")>0,1,0)
A35: 46157 | B35: =IF(A35="","",YEAR(A35)) | C35: =IF(A35="","",YEAR(A35)&"-Q"&ROUNDUP(MONTH(A35)/3,0)) | D35: 21/5940 | E35: Kleine Anfrage | F35: AfD | G35: Opposition | H35: 21 | I35: Bahnhoefe; Kriminalitaet | K35: =IF(OR(J35="",LEFT(E35,7)<>"Antwort"),"",IFERROR(A35-INDEX($A$2:$A$293,MATCH(J35,$D$2:$D$293,0)),"")) | L35: =IF(E35<>"Kleine Anfrage","",IFERROR(INDEX($D$2:$D$293,MATCH(D35,$J$2:$J$293,0)),"offen")) | M35: Entwicklung der Kriminalität im Bereich des Bahnhofs der Stadt Detmold im Jahr 2025 | N35: Fraktion der AfD | O35: PDF | Q35: Entwicklung / Kriminalität | R35: =IF(COUNTIF(Abstimmungen!$B$5:$B$2000,D35)-COUNTIFS(Abstimmungen!$B$5:$B$2000,D35,Abstimmungen!$D$5:$D$2000,"*berweisung*")>0,1,0)
A36: 46157 | B36: =IF(A36="","",YEAR(A36)) | C36: =IF(A36="","",YEAR(A36)&"-Q"&ROUNDUP(MONTH(A36)/3,0)) | D36: 21/5938 | E36: Kleine Anfrage | F36: AfD | G36: Opposition | H36: 21 | I36: Bahnhoefe; Kriminalitaet | K36: =IF(OR(J36="",LEFT(E36,7)<>"Antwort"),"",IFERROR(A36-INDEX($A$2:$A$293,MATCH(J36,$D$2:$D$293,0)),"")) | L36: =IF(E36<>"Kleine Anfrage","",IFERROR(INDEX($D$2:$D$293,MATCH(D36,$J$2:$J$293,0)),"offen")) | M36: Entwicklung der Kriminalität im Bereich des Bahnhofs der Stadt Herford im Jahr 2025 | N36: Fraktion der AfD | O36: PDF | Q36: Entwicklung / Kriminalität | R36: =IF(COUNTIF(Abstimmungen!$B$5:$B$2000,D36)-COUNTIFS(Abstimmungen!$B$5:$B$2000,D36,Abstimmungen!$D$5:$D$2000,"*berweisung*")>0,1,0)
A37: 46147 | B37: =IF(A37="","",YEAR(A37)) | C37: =IF(A37="","",YEAR(A37)&"-Q"&ROUNDUP(MONTH(A37)/3,0)) | D37: 21/5732 | E37: Antwort | F37: Bundesregierung | G37: Regierung | H37: 21 | I37: Bahnhoefe; Kriminalitaet | J37: 21/4586 | K37: =IF(OR(J37="",LEFT(E37,7)<>"Antwort"),"",IFERROR(A37-INDEX($A$2:$A$293,MATCH(J37,$D$2:$D$293,0)),"")) | L37: =IF(E37<>"Kleine Anfrage","",IFERROR(INDEX($D$2:$D$293,MATCH(D37,$J$2:$J$293,0)),"offen")) | M37: Straftaten an Thüringer Bahnhöfen und Flughäfen im Jahr 2025 | N37: Bundesregierung | O37: PDF | P37: AfD | R37: =IF(COUNTIF(Abstimmungen!$B$5:$B$2000,D37)-COUNTIFS(Abstimmungen!$B$5:$B$2000,D37,Abstimmungen!$D$5:$D$2000,"*berweisung*")>0,1,0)
A38: 46142 | B38: =IF(A38="","",YEAR(A38)) | C38: =IF(A38="","",YEAR(A38)&"-Q"&ROUNDUP(MONTH(A38)/3,0)) | D38: 21/5700 | E38: Unterrichtung | F38: Bundesregierung | G38: Regierung | H38: 21 | I38: Nahverkehr/SPNV; Finanzierung | K38: =IF(OR(J38="",LEFT(E38,7)<>"Antwort"),"",IFERROR(A38-INDEX($A$2:$A$293,MATCH(J38,$D$2:$D$293,0)),"")) | L38: =IF(E38<>"Kleine Anfrage","",IFERROR(INDEX($D$2:$D$293,MATCH(D38,$J$2:$J$293,0)),"offen")) | M38: Bericht der Bundesregierung zur Verwendung der Regionalisierungsmittel durch die Länder im Jahr 2019 | N38: Bundesregierung | O38: PDF | R38: =IF(COUNTIF(Abstimmungen!$B$5:$B$2000,D38)-COUNTIFS(Abstimmungen!$B$5:$B$2000,D38,Abstimmungen!$D$5:$D$2000,"*berweisung*")>0,1,0)
A39: 46140 | B39: =IF(A39="","",YEAR(A39)) | C39: =IF(A39="","",YEAR(A39)&"-Q"&ROUNDUP(MONTH(A39)/3,0)) | D39: 21/5663 | E39: Antwort | F39: Bundesregierung | G39: Regierung | H39: 21 | I39: Infrastruktur/Netz | J39: 21/4635 | K39: =IF(OR(J39="",LEFT(E39,7)<>"Antwort"),"",IFERROR(A39-INDEX($A$2:$A$293,MATCH(J39,$D$2:$D$293,0)),"")) | L39: =IF(E39<>"Kleine Anfrage","",IFERROR(INDEX($D$2:$D$293,MATCH(D39,$J$2:$J$293,0)),"offen")) | M39: Generalsanierung der Bahnstrecke Troisdorf-Wiesbaden | N39: Bundesregierung | O39: PDF | P39: Gruene | R39: =IF(COUNTIF(Abstimmungen!$B$5:$B$2000,D39)-COUNTIFS(Abstimmungen!$B$5:$B$2000,D39,Abstimmungen!$D$5:$D$2000,"*berweisung*")>0,1,0)
A40: 46139 | B40: =IF(A40="","",YEAR(A40)) | C40: =IF(A40="","",YEAR(A40)&"-Q"&ROUNDUP(MONTH(A40)/3,0)) | D40: 21/5610 | E40: Kleine Anfrage | F40: Gruene | G40: Opposition | H40: 21 | I40: Infrastruktur/Netz | K40: =IF(OR(J40="",LEFT(E40,7)<>"Antwort"),"",IFERROR(A40-INDEX($A$2:$A$293,MATCH(J40,$D$2:$D$293,0)),"")) | L40: =IF(E40<>"Kleine Anfrage","",IFERROR(INDEX($D$2:$D$293,MATCH(D40,$J$2:$J$293,0)),"offen")) | M40: Infrastrukturzustandsnoten Schieneninfrastruktur in Berlin | N40: Fraktion BÜNDNIS 90/DIE GRÜNEN | O40: PDF | R40: =IF(COUNTIF(Abstimmungen!$B$5:$B$2000,D40)-COUNTIFS(Abstimmungen!$B$5:$B$2000,D40,Abstimmungen!$D$5:$D$2000,"*berweisung*")>0,1,0)
...

Sheet Initiativen
A1: Eigene Initiativen je Fraktion
A2: Nur selbst eingebrachte Drucksachen. Antworten der Bundesregierung und Beschlussempfehlungen der Ausschuesse sind Reaktionen und hier bewusst nicht enthalten.
A4: Fraktion | B4: Rolle ab WP 21 | C4: Kleine Anfrage | D4: Antrag | E4: Entschließungsantrag | F4: Gesetzentwurf | G4: Gesamt | H4: Anteil
A5: CDU/CSU | B5: Regierungsfraktion | C5: =COUNTIFS(Drucksachen!$F$2:$F$293,$A5,Drucksachen!$E$2:$E$293,C$4) | D5: =COUNTIFS(Drucksachen!$F$2:$F$293,$A5,Drucksachen!$E$2:$E$293,D$4) | E5: =COUNTIFS(Drucksachen!$F$2:$F$293,$A5,Drucksachen!$E$2:$E$293,E$4) | F5: =COUNTIFS(Drucksachen!$F$2:$F$293,$A5,Drucksachen!$E$2:$E$293,F$4) | G5: =SUM(C5:F5) | H5: =IFERROR(G5/G$10,0)
A6: Gruene | B6: Opposition | C6: =COUNTIFS(Drucksachen!$F$2:$F$293,$A6,Drucksachen!$E$2:$E$293,C$4) | D6: =COUNTIFS(Drucksachen!$F$2:$F$293,$A6,Drucksachen!$E$2:$E$293,D$4) | E6: =COUNTIFS(Drucksachen!$F$2:$F$293,$A6,Drucksachen!$E$2:$E$293,E$4) | F6: =COUNTIFS(Drucksachen!$F$2:$F$293,$A6,Drucksachen!$E$2:$E$293,F$4) | G6: =SUM(C6:F6) | H6: =IFERROR(G6/G$10,0)
A7: AfD | B7: Opposition | C7: =COUNTIFS(Drucksachen!$F$2:$F$293,$A7,Drucksachen!$E$2:$E$293,C$4) | D7: =COUNTIFS(Drucksachen!$F$2:$F$293,$A7,Drucksachen!$E$2:$E$293,D$4) | E7: =COUNTIFS(Drucksachen!$F$2:$F$293,$A7,Drucksachen!$E$2:$E$293,E$4) | F7: =COUNTIFS(Drucksachen!$F$2:$F$293,$A7,Drucksachen!$E$2:$E$293,F$4) | G7: =SUM(C7:F7) | H7: =IFERROR(G7/G$10,0)
A8: Linke | B8: Opposition | C8: =COUNTIFS(Drucksachen!$F$2:$F$293,$A8,Drucksachen!$E$2:$E$293,C$4) | D8: =COUNTIFS(Drucksachen!$F$2:$F$293,$A8,Drucksachen!$E$2:$E$293,D$4) | E8: =COUNTIFS(Drucksachen!$F$2:$F$293,$A8,Drucksachen!$E$2:$E$293,E$4) | F8: =COUNTIFS(Drucksachen!$F$2:$F$293,$A8,Drucksachen!$E$2:$E$293,F$4) | G8: =SUM(C8:F8) | H8: =IFERROR(G8/G$10,0)
A9: Mehrere Fraktionen | B9: Fraktionsuebergreifend | C9: =COUNTIFS(Drucksachen!$F$2:$F$293,$A9,Drucksachen!$E$2:$E$293,C$4) | D9: =COUNTIFS(Drucksachen!$F$2:$F$293,$A9,Drucksachen!$E$2:$E$293,D$4) | E9: =COUNTIFS(Drucksachen!$F$2:$F$293,$A9,Drucksachen!$E$2:$E$293,E$4) | F9: =COUNTIFS(Drucksachen!$F$2:$F$293,$A9,Drucksachen!$E$2:$E$293,F$4) | G9: =SUM(C9:F9) | H9: =IFERROR(G9/G$10,0)
A10: Gesamt | C10: =SUM(C5:C9) | D10: =SUM(D5:D9) | E10: =SUM(E5:E9) | F10: =SUM(F5:F9) | G10: =SUM(G5:G9)

Sheet Zeitverlauf
A1: Drucksachen je Quartal
A3: Quartal | B3: CDU/CSU | C3: Gruene | D3: AfD | E3: Linke | F3: Mehrere Fraktionen | G3: Bundesregierung | H3: Ausschuesse | I3: Gesamt
A4: 2021-Q4 | B4: =COUNTIFS(Drucksachen!$C$2:$C$293,$A4,Drucksachen!$F$2:$F$293,B$3) | C4: =COUNTIFS(Drucksachen!$C$2:$C$293,$A4,Drucksachen!$F$2:$F$293,C$3) | D4: =COUNTIFS(Drucksachen!$C$2:$C$293,$A4,Drucksachen!$F$2:$F$293,D$3) | E4: =COUNTIFS(Drucksachen!$C$2:$C$293,$A4,Drucksachen!$F$2:$F$293,E$3) | F4: =COUNTIFS(Drucksachen!$C$2:$C$293,$A4,Drucksachen!$F$2:$F$293,F$3) | G4: =COUNTIFS(Drucksachen!$C$2:$C$293,$A4,Drucksachen!$F$2:$F$293,"Bundesregierung") | H4: =COUNTIFS(Drucksachen!$C$2:$C$293,$A4,Drucksachen!$G$2:$G$293,"Ausschuss") | I4: =COUNTIFS(Drucksachen!$C$2:$C$293,$A4)
A5: 2022-Q1 | B5: =COUNTIFS(Drucksachen!$C$2:$C$293,$A5,Drucksachen!$F$2:$F$293,B$3) | C5: =COUNTIFS(Drucksachen!$C$2:$C$293,$A5,Drucksachen!$F$2:$F$293,C$3) | D5: =COUNTIFS(Drucksachen!$C$2:$C$293,$A5,Drucksachen!$F$2:$F$293,D$3) | E5: =COUNTIFS(Drucksachen!$C$2:$C$293,$A5,Drucksachen!$F$2:$F$293,E$3) | F5: =COUNTIFS(Drucksachen!$C$2:$C$293,$A5,Drucksachen!$F$2:$F$293,F$3) | G5: =COUNTIFS(Drucksachen!$C$2:$C$293,$A5,Drucksachen!$F$2:$F$293,"Bundesregierung") | H5: =COUNTIFS(Drucksachen!$C$2:$C$293,$A5,Drucksachen!$G$2:$G$293,"Ausschuss") | I5: =COUNTIFS(Drucksachen!$C$2:$C$293,$A5)
A6: 2022-Q2 | B6: =COUNTIFS(Drucksachen!$C$2:$C$293,$A6,Drucksachen!$F$2:$F$293,B$3) | C6: =COUNTIFS(Drucksachen!$C$2:$C$293,$A6,Drucksachen!$F$2:$F$293,C$3) | D6: =COUNTIFS(Drucksachen!$C$2:$C$293,$A6,Drucksachen!$F$2:$F$293,D$3) | E6: =COUNTIFS(Drucksachen!$C$2:$C$293,$A6,Drucksachen!$F$2:$F$293,E$3) | F6: =COUNTIFS(Drucksachen!$C$2:$C$293,$A6,Drucksachen!$F$2:$F$293,F$3) | G6: =COUNTIFS(Drucksachen!$C$2:$C$293,$A6,Drucksachen!$F$2:$F$293,"Bundesregierung") | H6: =COUNTIFS(Drucksachen!$C$2:$C$293,$A6,Drucksachen!$G$2:$G$293,"Ausschuss") | I6: =COUNTIFS(Drucksachen!$C$2:$C$293,$A6)
A7: 2022-Q3 | B7: =COUNTIFS(Drucksachen!$C$2:$C$293,$A7,Drucksachen!$F$2:$F$293,B$3) | C7: =COUNTIFS(Drucksachen!$C$2:$C$293,$A7,Drucksachen!$F$2:$F$293,C$3) | D7: =COUNTIFS(Drucksachen!$C$2:$C$293,$A7,Drucksachen!$F$2:$F$293,D$3) | E7: =COUNTIFS(Drucksachen!$C$2:$C$293,$A7,Drucksachen!$F$2:$F$293,E$3) | F7: =COUNTIFS(Drucksachen!$C$2:$C$293,$A7,Drucksachen!$F$2:$F$293,F$3) | G7: =COUNTIFS(Drucksachen!$C$2:$C$293,$A7,Drucksachen!$F$2:$F$293,"Bundesregierung") | H7: =COUNTIFS(Drucksachen!$C$2:$C$293,$A7,Drucksachen!$G$2:$G$293,"Ausschuss") | I7: =COUNTIFS(Drucksachen!$C$2:$C$293,$A7)
A8: 2022-Q4 | B8: =COUNTIFS(Drucksachen!$C$2:$C$293,$A8,Drucksachen!$F$2:$F$293,B$3) | C8: =COUNTIFS(Drucksachen!$C$2:$C$293,$A8,Drucksachen!$F$2:$F$293,C$3) | D8: =COUNTIFS(Drucksachen!$C$2:$C$293,$A8,Drucksachen!$F$2:$F$293,D$3) | E8: =COUNTIFS(Drucksachen!$C$2:$C$293,$A8,Drucksachen!$F$2:$F$293,E$3) | F8: =COUNTIFS(Drucksachen!$C$2:$C$293,$A8,Drucksachen!$F$2:$F$293,F$3) | G8: =COUNTIFS(Drucksachen!$C$2:$C$293,$A8,Drucksachen!$F$2:$F$293,"Bundesregierung") | H8: =COUNTIFS(Drucksachen!$C$2:$C$293,$A8,Drucksachen!$G$2:$G$293,"Ausschuss") | I8: =COUNTIFS(Drucksachen!$C$2:$C$293,$A8)
A9: 2023-Q1 | B9: =COUNTIFS(Drucksachen!$C$2:$C$293,$A9,Drucksachen!$F$2:$F$293,B$3) | C9: =COUNTIFS(Drucksachen!$C$2:$C$293,$A9,Drucksachen!$F$2:$F$293,C$3) | D9: =COUNTIFS(Drucksachen!$C$2:$C$293,$A9,Drucksachen!$F$2:$F$293,D$3) | E9: =COUNTIFS(Drucksachen!$C$2:$C$293,$A9,Drucksachen!$F$2:$F$293,E$3) | F9: =COUNTIFS(Drucksachen!$C$2:$C$293,$A9,Drucksachen!$F$2:$F$293,F$3) | G9: =COUNTIFS(Drucksachen!$C$2:$C$293,$A9,Drucksachen!$F$2:$F$293,"Bundesregierung") | H9: =COUNTIFS(Drucksachen!$C$2:$C$293,$A9,Drucksachen!$G$2:$G$293,"Ausschuss") | I9: =COUNTIFS(Drucksachen!$C$2:$C$293,$A9)
A10: 2023-Q2 | B10: =COUNTIFS(Drucksachen!$C$2:$C$293,$A10,Drucksachen!$F$2:$F$293,B$3) | C10: =COUNTIFS(Drucksachen!$C$2:$C$293,$A10,Drucksachen!$F$2:$F$293,C$3) | D10: =COUNTIFS(Drucksachen!$C$2:$C$293,$A10,Drucksachen!$F$2:$F$293,D$3) | E10: =COUNTIFS(Drucksachen!$C$2:$C$293,$A10,Drucksachen!$F$2:$F$293,E$3) | F10: =COUNTIFS(Drucksachen!$C$2:$C$293,$A10,Drucksachen!$F$2:$F$293,F$3) | G10: =COUNTIFS(Drucksachen!$C$2:$C$293,$A10,Drucksachen!$F$2:$F$293,"Bundesregierung") | H10: =COUNTIFS(Drucksachen!$C$2:$C$293,$A10,Drucksachen!$G$2:$G$293,"Ausschuss") | I10: =COUNTIFS(Drucksachen!$C$2:$C$293,$A10)
A11: 2023-Q3 | B11: =COUNTIFS(Drucksachen!$C$2:$C$293,$A11,Drucksachen!$F$2:$F$293,B$3) | C11: =COUNTIFS(Drucksachen!$C$2:$C$293,$A11,Drucksachen!$F$2:$F$293,C$3) | D11: =COUNTIFS(Drucksachen!$C$2:$C$293,$A11,Drucksachen!$F$2:$F$293,D$3) | E11: =COUNTIFS(Drucksachen!$C$2:$C$293,$A11,Drucksachen!$F$2:$F$293,E$3) | F11: =COUNTIFS(Drucksachen!$C$2:$C$293,$A11,Drucksachen!$F$2:$F$293,F$3) | G11: =COUNTIFS(Drucksachen!$C$2:$C$293,$A11,Drucksachen!$F$2:$F$293,"Bundesregierung") | H11: =COUNTIFS(Drucksachen!$C$2:$C$293,$A11,Drucksachen!$G$2:$G$293,"Ausschuss") | I11: =COUNTIFS(Drucksachen!$C$2:$C$293,$A11)
A12: 2023-Q4 | B12: =COUNTIFS(Drucksachen!$C$2:$C$293,$A12,Drucksachen!$F$2:$F$293,B$3) | C12: =COUNTIFS(Drucksachen!$C$2:$C$293,$A12,Drucksachen!$F$2:$F$293,C$3) | D12: =COUNTIFS(Drucksachen!$C$2:$C$293,$A12,Drucksachen!$F$2:$F$293,D$3) | E12: =COUNTIFS(Drucksachen!$C$2:$C$293,$A12,Drucksachen!$F$2:$F$293,E$3) | F12: =COUNTIFS(Drucksachen!$C$2:$C$293,$A12,Drucksachen!$F$2:$F$293,F$3) | G12: =COUNTIFS(Drucksachen!$C$2:$C$293,$A12,Drucksachen!$F$2:$F$293,"Bundesregierung") | H12: =COUNTIFS(Drucksachen!$C$2:$C$293,$A12,Drucksachen!$G$2:$G$293,"Ausschuss") | I12: =COUNTIFS(Drucksachen!$C$2:$C$293,$A12)
A13: 2024-Q1 | B13: =COUNTIFS(Drucksachen!$C$2:$C$293,$A13,Drucksachen!$F$2:$F$293,B$3) | C13: =COUNTIFS(Drucksachen!$C$2:$C$293,$A13,Drucksachen!$F$2:$F$293,C$3) | D13: =COUNTIFS(Drucksachen!$C$2:$C$293,$A13,Drucksachen!$F$2:$F$293,D$3) | E13: =COUNTIFS(Drucksachen!$C$2:$C$293,$A13,Drucksachen!$F$2:$F$293,E$3) | F13: =COUNTIFS(Drucksachen!$C$2:$C$293,$A13,Drucksachen!$F$2:$F$293,F$3) | G13: =COUNTIFS(Drucksachen!$C$2:$C$293,$A13,Drucksachen!$F$2:$F$293,"Bundesregierung") | H13: =COUNTIFS(Drucksachen!$C$2:$C$293,$A13,Drucksachen!$G$2:$G$293,"Ausschuss") | I13: =COUNTIFS(Drucksachen!$C$2:$C$293,$A13)
A14: 2024-Q2 | B14: =COUNTIFS(Drucksachen!$C$2:$C$293,$A14,Drucksachen!$F$2:$F$293,B$3) | C14: =COUNTIFS(Drucksachen!$C$2:$C$293,$A14,Drucksachen!$F$2:$F$293,C$3) | D14: =COUNTIFS(Drucksachen!$C$2:$C$293,$A14,Drucksachen!$F$2:$F$293,D$3) | E14: =COUNTIFS(Drucksachen!$C$2:$C$293,$A14,Drucksachen!$F$2:$F$293,E$3) | F14: =COUNTIFS(Drucksachen!$C$2:$C$293,$A14,Drucksachen!$F$2:$F$293,F$3) | G14: =COUNTIFS(Drucksachen!$C$2:$C$293,$A14,Drucksachen!$F$2:$F$293,"Bundesregierung") | H14: =COUNTIFS(Drucksachen!$C$2:$C$293,$A14,Drucksachen!$G$2:$G$293,"Ausschuss") | I14: =COUNTIFS(Drucksachen!$C$2:$C$293,$A14)
A15: 2024-Q3 | B15: =COUNTIFS(Drucksachen!$C$2:$C$293,$A15,Drucksachen!$F$2:$F$293,B$3) | C15: =COUNTIFS(Drucksachen!$C$2:$C$293,$A15,Drucksachen!$F$2:$F$293,C$3) | D15: =COUNTIFS(Drucksachen!$C$2:$C$293,$A15,Drucksachen!$F$2:$F$293,D$3) | E15: =COUNTIFS(Drucksachen!$C$2:$C$293,$A15,Drucksachen!$F$2:$F$293,E$3) | F15: =COUNTIFS(Drucksachen!$C$2:$C$293,$A15,Drucksachen!$F$2:$F$293,F$3) | G15: =COUNTIFS(Drucksachen!$C$2:$C$293,$A15,Drucksachen!$F$2:$F$293,"Bundesregierung") | H15: =COUNTIFS(Drucksachen!$C$2:$C$293,$A15,Drucksachen!$G$2:$G$293,"Ausschuss") | I15: =COUNTIFS(Drucksachen!$C$2:$C$293,$A15)
... A23: 2026-Q3 | B23: =COUNTIFS(Drucksachen!$C$2:$C$293,$A23,Drucksachen!$F$2:$F$293,B$3) | C23: =COUNTIFS(Drucksachen!$C$2:$C$293,$A23,Drucksachen!$F$2:$F$293,C$3) | D23: =COUNTIFS(Drucksachen!$C$2:$C$293,$A23,Drucksachen!$F$2:$F$293,D$3) | E23: =COUNTIFS(Drucksachen!$C$2:$C$293,$A23,Drucksachen!$F$2:$F$293,E$3) | F23: =COUNTIFS(Drucksachen!$C$2:$C$293,$A23,Drucksachen!$F$2:$F$293,F$3) | G23: =COUNTIFS(Drucksachen!$C$2:$C$293,$A23,Drucksachen!$F$2:$F$293,"Bundesregierung") | H23: =COUNTIFS(Drucksachen!$C$2:$C$293,$A23,Drucksachen!$G$2:$G$293,"Ausschuss") | I23: =COUNTIFS(Drucksachen!$C$2:$C$293,$A23)

Sheet Themen
A1: Themen im Zeitverlauf
A2: Mehrfachnennung moeglich: eine Drucksache kann mehreren Themen zugeordnet sein, die Spaltensummen uebersteigen daher die Zahl der Drucksachen.
A4: Thema | B4: 2021 | C4: 2022 | D4: 2023 | E4: 2024 | F4: 2025 | G4: 2026 | H4: Gesamt | I4: davon Opposition | K4: Hilfsbereich Initiativtypen
A5: Bahnhoefe | B5: =SUMPRODUCT(ISNUMBER(SEARCH($A5,Drucksachen!$I$2:$I$293))*(Drucksachen!$B$2:$B$293=B$4)) | C5: =SUMPRODUCT(ISNUMBER(SEARCH($A5,Drucksachen!$I$2:$I$293))*(Drucksachen!$B$2:$B$293=C$4)) | D5: =SUMPRODUCT(ISNUMBER(SEARCH($A5,Drucksachen!$I$2:$I$293))*(Drucksachen!$B$2:$B$293=D$4)) | E5: =SUMPRODUCT(ISNUMBER(SEARCH($A5,Drucksachen!$I$2:$I$293))*(Drucksachen!$B$2:$B$293=E$4)) | F5: =SUMPRODUCT(ISNUMBER(SEARCH($A5,Drucksachen!$I$2:$I$293))*(Drucksachen!$B$2:$B$293=F$4)) | G5: =SUMPRODUCT(ISNUMBER(SEARCH($A5,Drucksachen!$I$2:$I$293))*(Drucksachen!$B$2:$B$293=G$4)) | H5: =SUM(B5:G5) | I5: =SUMPRODUCT(ISNUMBER(SEARCH($A5,Drucksachen!$I$2:$I$293))*(Drucksachen!$G$2:$G$293="Opposition")) | K5: Kleine Anfrage
A6: Kriminalitaet | B6: =SUMPRODUCT(ISNUMBER(SEARCH($A6,Drucksachen!$I$2:$I$293))*(Drucksachen!$B$2:$B$293=B$4)) | C6: =SUMPRODUCT(ISNUMBER(SEARCH($A6,Drucksachen!$I$2:$I$293))*(Drucksachen!$B$2:$B$293=C$4)) | D6: =SUMPRODUCT(ISNUMBER(SEARCH($A6,Drucksachen!$I$2:$I$293))*(Drucksachen!$B$2:$B$293=D$4)) | E6: =SUMPRODUCT(ISNUMBER(SEARCH($A6,Drucksachen!$I$2:$I$293))*(Drucksachen!$B$2:$B$293=E$4)) | F6: =SUMPRODUCT(ISNUMBER(SEARCH($A6,Drucksachen!$I$2:$I$293))*(Drucksachen!$B$2:$B$293=F$4)) | G6: =SUMPRODUCT(ISNUMBER(SEARCH($A6,Drucksachen!$I$2:$I$293))*(Drucksachen!$B$2:$B$293=G$4)) | H6: =SUM(B6:G6) | I6: =SUMPRODUCT(ISNUMBER(SEARCH($A6,Drucksachen!$I$2:$I$293))*(Drucksachen!$G$2:$G$293="Opposition")) | K6: Antrag
A7: Sonstiges | B7: =SUMPRODUCT(ISNUMBER(SEARCH($A7,Drucksachen!$I$2:$I$293))*(Drucksachen!$B$2:$B$293=B$4)) | C7: =SUMPRODUCT(ISNUMBER(SEARCH($A7,Drucksachen!$I$2:$I$293))*(Drucksachen!$B$2:$B$293=C$4)) | D7: =SUMPRODUCT(ISNUMBER(SEARCH($A7,Drucksachen!$I$2:$I$293))*(Drucksachen!$B$2:$B$293=D$4)) | E7: =SUMPRODUCT(ISNUMBER(SEARCH($A7,Drucksachen!$I$2:$I$293))*(Drucksachen!$B$2:$B$293=E$4)) | F7: =SUMPRODUCT(ISNUMBER(SEARCH($A7,Drucksachen!$I$2:$I$293))*(Drucksachen!$B$2:$B$293=F$4)) | G7: =SUMPRODUCT(ISNUMBER(SEARCH($A7,Drucksachen!$I$2:$I$293))*(Drucksachen!$B$2:$B$293=G$4)) | H7: =SUM(B7:G7) | I7: =SUMPRODUCT(ISNUMBER(SEARCH($A7,Drucksachen!$I$2:$I$293))*(Drucksachen!$G$2:$G$293="Opposition")) | K7: Entschließungsantrag
A8: Infrastruktur/Netz | B8: =SUMPRODUCT(ISNUMBER(SEARCH($A8,Drucksachen!$I$2:$I$293))*(Drucksachen!$B$2:$B$293=B$4)) | C8: =SUMPRODUCT(ISNUMBER(SEARCH($A8,Drucksachen!$I$2:$I$293))*(Drucksachen!$B$2:$B$293=C$4)) | D8: =SUMPRODUCT(ISNUMBER(SEARCH($A8,Drucksachen!$I$2:$I$293))*(Drucksachen!$B$2:$B$293=D$4)) | E8: =SUMPRODUCT(ISNUMBER(SEARCH($A8,Drucksachen!$I$2:$I$293))*(Drucksachen!$B$2:$B$293=E$4)) | F8: =SUMPRODUCT(ISNUMBER(SEARCH($A8,Drucksachen!$I$2:$I$293))*(Drucksachen!$B$2:$B$293=F$4)) | G8: =SUMPRODUCT(ISNUMBER(SEARCH($A8,Drucksachen!$I$2:$I$293))*(Drucksachen!$B$2:$B$293=G$4)) | H8: =SUM(B8:G8) | I8: =SUMPRODUCT(ISNUMBER(SEARCH($A8,Drucksachen!$I$2:$I$293))*(Drucksachen!$G$2:$G$293="Opposition")) | K8: Gesetzentwurf
A9: Konzernstruktur/DB AG | B9: =SUMPRODUCT(ISNUMBER(SEARCH($A9,Drucksachen!$I$2:$I$293))*(Drucksachen!$B$2:$B$293=B$4)) | C9: =SUMPRODUCT(ISNUMBER(SEARCH($A9,Drucksachen!$I$2:$I$293))*(Drucksachen!$B$2:$B$293=C$4)) | D9: =SUMPRODUCT(ISNUMBER(SEARCH($A9,Drucksachen!$I$2:$I$293))*(Drucksachen!$B$2:$B$293=D$4)) | E9: =SUMPRODUCT(ISNUMBER(SEARCH($A9,Drucksachen!$I$2:$I$293))*(Drucksachen!$B$2:$B$293=E$4)) | F9: =SUMPRODUCT(ISNUMBER(SEARCH($A9,Drucksachen!$I$2:$I$293))*(Drucksachen!$B$2:$B$293=F$4)) | G9: =SUMPRODUCT(ISNUMBER(SEARCH($A9,Drucksachen!$I$2:$I$293))*(Drucksachen!$B$2:$B$293=G$4)) | H9: =SUM(B9:G9) | I9: =SUMPRODUCT(ISNUMBER(SEARCH($A9,Drucksachen!$I$2:$I$293))*(Drucksachen!$G$2:$G$293="Opposition"))
A10: Sicherheit | B10: =SUMPRODUCT(ISNUMBER(SEARCH($A10,Drucksachen!$I$2:$I$293))*(Drucksachen!$B$2:$B$293=B$4)) | C10: =SUMPRODUCT(ISNUMBER(SEARCH($A10,Drucksachen!$I$2:$I$293))*(Drucksachen!$B$2:$B$293=C$4)) | D10: =SUMPRODUCT(ISNUMBER(SEARCH($A10,Drucksachen!$I$2:$I$293))*(Drucksachen!$B$2:$B$293=D$4)) | E10: =SUMPRODUCT(ISNUMBER(SEARCH($A10,Drucksachen!$I$2:$I$293))*(Drucksachen!$B$2:$B$293=E$4)) | F10: =SUMPRODUCT(ISNUMBER(SEARCH($A10,Drucksachen!$I$2:$I$293))*(Drucksachen!$B$2:$B$293=F$4)) | G10: =SUMPRODUCT(ISNUMBER(SEARCH($A10,Drucksachen!$I$2:$I$293))*(Drucksachen!$B$2:$B$293=G$4)) | H10: =SUM(B10:G10) | I10: =SUMPRODUCT(ISNUMBER(SEARCH($A10,Drucksachen!$I$2:$I$293))*(Drucksachen!$G$2:$G$293="Opposition"))
A11: Finanzierung | B11: =SUMPRODUCT(ISNUMBER(SEARCH($A11,Drucksachen!$I$2:$I$293))*(Drucksachen!$B$2:$B$293=B$4)) | C11: =SUMPRODUCT(ISNUMBER(SEARCH($A11,Drucksachen!$I$2:$I$293))*(Drucksachen!$B$2:$B$293=C$4)) | D11: =SUMPRODUCT(ISNUMBER(SEARCH($A11,Drucksachen!$I$2:$I$293))*(Drucksachen!$B$2:$B$293=D$4)) | E11: =SUMPRODUCT(ISNUMBER(SEARCH($A11,Drucksachen!$I$2:$I$293))*(Drucksachen!$B$2:$B$293=E$4)) | F11: =SUMPRODUCT(ISNUMBER(SEARCH($A11,Drucksachen!$I$2:$I$293))*(Drucksachen!$B$2:$B$293=F$4)) | G11: =SUMPRODUCT(ISNUMBER(SEARCH($A11,Drucksachen!$I$2:$I$293))*(Drucksachen!$B$2:$B$293=G$4)) | H11: =SUM(B11:G11) | I11: =SUMPRODUCT(ISNUMBER(SEARCH($A11,Drucksachen!$I$2:$I$293))*(Drucksachen!$G$2:$G$293="Opposition"))
A12: Puenktlichkeit/Qualitaet | B12: =SUMPRODUCT(ISNUMBER(SEARCH($A12,Drucksachen!$I$2:$I$293))*(Drucksachen!$B$2:$B$293=B$4)) | C12: =SUMPRODUCT(ISNUMBER(SEARCH($A12,Drucksachen!$I$2:$I$293))*(Drucksachen!$B$2:$B$293=C$4)) | D12: =SUMPRODUCT(ISNUMBER(SEARCH($A12,Drucksachen!$I$2:$I$293))*(Drucksachen!$B$2:$B$293=D$4)) | E12: =SUMPRODUCT(ISNUMBER(SEARCH($A12,Drucksachen!$I$2:$I$293))*(Drucksachen!$B$2:$B$293=E$4)) | F12: =SUMPRODUCT(ISNUMBER(SEARCH($A12,Drucksachen!$I$2:$I$293))*(Drucksachen!$B$2:$B$293=F$4)) | G12: =SUMPRODUCT(ISNUMBER(SEARCH($A12,Drucksachen!$I$2:$I$293))*(Drucksachen!$B$2:$B$293=G$4)) | H12: =SUM(B12:G12) | I12: =SUMPRODUCT(ISNUMBER(SEARCH($A12,Drucksachen!$I$2:$I$293))*(Drucksachen!$G$2:$G$293="Opposition"))
A13: Barrierefreiheit | B13: =SUMPRODUCT(ISNUMBER(SEARCH($A13,Drucksachen!$I$2:$I$293))*(Drucksachen!$B$2:$B$293=B$4)) | C13: =SUMPRODUCT(ISNUMBER(SEARCH($A13,Drucksachen!$I$2:$I$293))*(Drucksachen!$B$2:$B$293=C$4)) | D13: =SUMPRODUCT(ISNUMBER(SEARCH($A13,Drucksachen!$I$2:$I$293))*(Drucksachen!$B$2:$B$293=D$4)) | E13: =SUMPRODUCT(ISNUMBER(SEARCH($A13,Drucksachen!$I$2:$I$293))*(Drucksachen!$B$2:$B$293=E$4)) | F13: =SUMPRODUCT(ISNUMBER(SEARCH($A13,Drucksachen!$I$2:$I$293))*(Drucksachen!$B$2:$B$293=F$4)) | G13: =SUMPRODUCT(ISNUMBER(SEARCH($A13,Drucksachen!$I$2:$I$293))*(Drucksachen!$B$2:$B$293=G$4)) | H13: =SUM(B13:G13) | I13: =SUMPRODUCT(ISNUMBER(SEARCH($A13,Drucksachen!$I$2:$I$293))*(Drucksachen!$G$2:$G$293="Opposition"))
A14: Deutschlandticket | B14: =SUMPRODUCT(ISNUMBER(SEARCH($A14,Drucksachen!$I$2:$I$293))*(Drucksachen!$B$2:$B$293=B$4)) | C14: =SUMPRODUCT(ISNUMBER(SEARCH($A14,Drucksachen!$I$2:$I$293))*(Drucksachen!$B$2:$B$293=C$4)) | D14: =SUMPRODUCT(ISNUMBER(SEARCH($A14,Drucksachen!$I$2:$I$293))*(Drucksachen!$B$2:$B$293=D$4)) | E14: =SUMPRODUCT(ISNUMBER(SEARCH($A14,Drucksachen!$I$2:$I$293))*(Drucksachen!$B$2:$B$293=E$4)) | F14: =SUMPRODUCT(ISNUMBER(SEARCH($A14,Drucksachen!$I$2:$I$293))*(Drucksachen!$B$2:$B$293=F$4)) | G14: =SUMPRODUCT(ISNUMBER(SEARCH($A14,Drucksachen!$I$2:$I$293))*(Drucksachen!$B$2:$B$293=G$4)) | H14: =SUM(B14:G14) | I14: =SUMPRODUCT(ISNUMBER(SEARCH($A14,Drucksachen!$I$2:$I$293))*(Drucksachen!$G$2:$G$293="Opposition"))
A15: Nahverkehr/SPNV | B15: =SUMPRODUCT(ISNUMBER(SEARCH($A15,Drucksachen!$I$2:$I$293))*(Drucksachen!$B$2:$B$293=B$4)) | C15: =SUMPRODUCT(ISNUMBER(SEARCH($A15,Drucksachen!$I$2:$I$293))*(Drucksachen!$B$2:$B$293=C$4)) | D15: =SUMPRODUCT(ISNUMBER(SEARCH($A15,Drucksachen!$I$2:$I$293))*(Drucksachen!$B$2:$B$293=D$4)) | E15: =SUMPRODUCT(ISNUMBER(SEARCH($A15,Drucksachen!$I$2:$I$293))*(Drucksachen!$B$2:$B$293=E$4)) | F15: =SUMPRODUCT(ISNUMBER(SEARCH($A15,Drucksachen!$I$2:$I$293))*(Drucksachen!$B$2:$B$293=F$4)) | G15: =SUMPRODUCT(ISNUMBER(SEARCH($A15,Drucksachen!$I$2:$I$293))*(Drucksachen!$B$2:$B$293=G$4)) | H15: =SUM(B15:G15) | I15: =SUMPRODUCT(ISNUMBER(SEARCH($A15,Drucksachen!$I$2:$I$293))*(Drucksachen!$G$2:$G$293="Opposition"))
A16: Deutschlandtakt/Fahrplan | B16: =SUMPRODUCT(ISNUMBER(SEARCH($A16,Drucksachen!$I$2:$I$293))*(Drucksachen!$B$2:$B$293=B$4)) | C16: =SUMPRODUCT(ISNUMBER(SEARCH($A16,Drucksachen!$I$2:$I$293))*(Drucksachen!$B$2:$B$293=C$4)) | D16: =SUMPRODUCT(ISNUMBER(SEARCH($A16,Drucksachen!$I$2:$I$293))*(Drucksachen!$B$2:$B$293=D$4)) | E16: =SUMPRODUCT(ISNUMBER(SEARCH($A16,Drucksachen!$I$2:$I$293))*(Drucksachen!$B$2:$B$293=E$4)) | F16: =SUMPRODUCT(ISNUMBER(SEARCH($A16,Drucksachen!$I$2:$I$293))*(Drucksachen!$B$2:$B$293=F$4)) | G16: =SUMPRODUCT(ISNUMBER(SEARCH($A16,Drucksachen!$I$2:$I$293))*(Drucksachen!$B$2:$B$293=G$4)) | H16: =SUM(B16:G16) | I16: =SUMPRODUCT(ISNUMBER(SEARCH($A16,Drucksachen!$I$2:$I$293))*(Drucksachen!$G$2:$G$293="Opposition"))
A17: Personal | B17: =SUMPRODUCT(ISNUMBER(SEARCH($A17,Drucksachen!$I$2:$I$293))*(Drucksachen!$B$2:$B$293=B$4)) | C17: =SUMPRODUCT(ISNUMBER(SEARCH($A17,Drucksachen!$I$2:$I$293))*(Drucksachen!$B$2:$B$293=C$4)) | D17: =SUMPRODUCT(ISNUMBER(SEARCH($A17,Drucksachen!$I$2:$I$293))*(Drucksachen!$B$2:$B$293=D$4)) | E17: =SUMPRODUCT(ISNUMBER(SEARCH($A17,Drucksachen!$I$2:$I$293))*(Drucksachen!$B$2:$B$293=E$4)) | F17: =SUMPRODUCT(ISNUMBER(SEARCH($A17,Drucksachen!$I$2:$I$293))*(Drucksachen!$B$2:$B$293=F$4)) | G17: =SUMPRODUCT(ISNUMBER(SEARCH($A17,Drucksachen!$I$2:$I$293))*(Drucksachen!$B$2:$B$293=G$4)) | H17: =SUM(B17:G17) | I17: =SUMPRODUCT(ISNUMBER(SEARCH($A17,Drucksachen!$I$2:$I$293))*(Drucksachen!$G$2:$G$293="Opposition"))
A18: Gueterverkehr | B18: =SUMPRODUCT(ISNUMBER(SEARCH($A18,Drucksachen!$I$2:$I$293))*(Drucksachen!$B$2:$B$293=B$4)) | C18: =SUMPRODUCT(ISNUMBER(SEARCH($A18,Drucksachen!$I$2:$I$293))*(Drucksachen!$B$2:$B$293=C$4)) | D18: =SUMPRODUCT(ISNUMBER(SEARCH($A18,Drucksachen!$I$2:$I$293))*(Drucksachen!$B$2:$B$293=D$4)) | E18: =SUMPRODUCT(ISNUMBER(SEARCH($A18,Drucksachen!$I$2:$I$293))*(Drucksachen!$B$2:$B$293=E$4)) | F18: =SUMPRODUCT(ISNUMBER(SEARCH($A18,Drucksachen!$I$2:$I$293))*(Drucksachen!$B$2:$B$293=F$4)) | G18: =SUMPRODUCT(ISNUMBER(SEARCH($A18,Drucksachen!$I$2:$I$293))*(Drucksachen!$B$2:$B$293=G$4)) | H18: =SUM(B18:G18) | I18: =SUMPRODUCT(ISNUMBER(SEARCH($A18,Drucksachen!$I$2:$I$293))*(Drucksachen!$G$2:$G$293="Opposition"))
A21: Welche Fraktion bringt welches Thema ein
A22: Nur eigene Initiativen: Kleine Anfrage, Antrag, Entschließungsantrag, Gesetzentwurf. Antworten der Bundesregierung und Beschlussempfehlungen der Ausschuesse bleiben aussen vor, sie haben keinen politischen Urheber. Mehrfachnennung moeglich, eine Drucksache kann mehrere Themen tragen. Die Spalte Schwerpunkt nennt bei Gleichstand die in der Kopfzeile zuerst stehende Fraktion.
A24: Thema | B24: CDU/CSU | C24: Gruene | D24: AfD | E24: Linke | F24: Mehrere Fraktionen | G24: Initiativen gesamt | H24: Schwerpunkt bei
A25: Bahnhoefe | B25: =SUMPRODUCT(ISNUMBER(SEARCH($A25,Drucksachen!$I$2:$I$293))*(Drucksachen!$F$2:$F$293=B$24)*(COUNTIF(Themen!$K$5:$K$8,Drucksachen!$E$2:$E$293)>0)) | C25: =SUMPRODUCT(ISNUMBER(SEARCH($A25,Drucksachen!$I$2:$I$293))*(Drucksachen!$F$2:$F$293=C$24)*(COUNTIF(Themen!$K$5:$K$8,Drucksachen!$E$2:$E$293)>0)) | D25: =SUMPRODUCT(ISNUMBER(SEARCH($A25,Drucksachen!$I$2:$I$293))*(Drucksachen!$F$2:$F$293=D$24)*(COUNTIF(Themen!$K$5:$K$8,Drucksachen!$E$2:$E$293)>0)) | E25: =SUMPRODUCT(ISNUMBER(SEARCH($A25,Drucksachen!$I$2:$I$293))*(Drucksachen!$F$2:$F$293=E$24)*(COUNTIF(Themen!$K$5:$K$8,Drucksachen!$E$2:$E$293)>0)) | F25: =SUMPRODUCT(ISNUMBER(SEARCH($A25,Drucksachen!$I$2:$I$293))*(Drucksachen!$F$2:$F$293=F$24)*(COUNTIF(Themen!$K$5:$K$8,Drucksachen!$E$2:$E$293)>0)) | G25: =SUM(B25:F25) | H25: =IF(G25=0,"",INDEX($B$24:$F$24,MATCH(MAX(B25:F25),B25:F25,0)))
A26: Kriminalitaet | B26: =SUMPRODUCT(ISNUMBER(SEARCH($A26,Drucksachen!$I$2:$I$293))*(Drucksachen!$F$2:$F$293=B$24)*(COUNTIF(Themen!$K$5:$K$8,Drucksachen!$E$2:$E$293)>0)) | C26: =SUMPRODUCT(ISNUMBER(SEARCH($A26,Drucksachen!$I$2:$I$293))*(Drucksachen!$F$2:$F$293=C$24)*(COUNTIF(Themen!$K$5:$K$8,Drucksachen!$E$2:$E$293)>0)) | D26: =SUMPRODUCT(ISNUMBER(SEARCH($A26,Drucksachen!$I$2:$I$293))*(Drucksachen!$F$2:$F$293=D$24)*(COUNTIF(Themen!$K$5:$K$8,Drucksachen!$E$2:$E$293)>0)) | E26: =SUMPRODUCT(ISNUMBER(SEARCH($A26,Drucksachen!$I$2:$I$293))*(Drucksachen!$F$2:$F$293=E$24)*(COUNTIF(Themen!$K$5:$K$8,Drucksachen!$E$2:$E$293)>0)) | F26: =SUMPRODUCT(ISNUMBER(SEARCH($A26,Drucksachen!$I$2:$I$293))*(Drucksachen!$F$2:$F$293=F$24)*(COUNTIF(Themen!$K$5:$K$8,Drucksachen!$E$2:$E$293)>0)) | G26: =SUM(B26:F26) | H26: =IF(G26=0,"",INDEX($B$24:$F$24,MATCH(MAX(B26:F26),B26:F26,0)))
A27: Sonstiges | B27: =SUMPRODUCT(ISNUMBER(SEARCH($A27,Drucksachen!$I$2:$I$293))*(Drucksachen!$F$2:$F$293=B$24)*(COUNTIF(Themen!$K$5:$K$8,Drucksachen!$E$2:$E$293)>0)) | C27: =SUMPRODUCT(ISNUMBER(SEARCH($A27,Drucksachen!$I$2:$I$293))*(Drucksachen!$F$2:$F$293=C$24)*(COUNTIF(Themen!$K$5:$K$8,Drucksachen!$E$2:$E$293)>0)) | D27: =SUMPRODUCT(ISNUMBER(SEARCH($A27,Drucksachen!$I$2:$I$293))*(Drucksachen!$F$2:$F$293=D$24)*(COUNTIF(Themen!$K$5:$K$8,Drucksachen!$E$2:$E$293)>0)) | E27: =SUMPRODUCT(ISNUMBER(SEARCH($A27,Drucksachen!$I$2:$I$293))*(Drucksachen!$F$2:$F$293=E$24)*(COUNTIF(Themen!$K$5:$K$8,Drucksachen!$E$2:$E$293)>0)) | F27: =SUMPRODUCT(ISNUMBER(SEARCH($A27,Drucksachen!$I$2:$I$293))*(Drucksachen!$F$2:$F$293=F$24)*(COUNTIF(Themen!$K$5:$K$8,Drucksachen!$E$2:$E$293)>0)) | G27: =SUM(B27:F27) | H27: =IF(G27=0,"",INDEX($B$24:$F$24,MATCH(MAX(B27:F27),B27:F27,0)))
A28: Infrastruktur/Netz | B28: =SUMPRODUCT(ISNUMBER(SEARCH($A28,Drucksachen!$I$2:$I$293))*(Drucksachen!$F$2:$F$293=B$24)*(COUNTIF(Themen!$K$5:$K$8,Drucksachen!$E$2:$E$293)>0)) | C28: =SUMPRODUCT(ISNUMBER(SEARCH($A28,Drucksachen!$I$2:$I$293))*(Drucksachen!$F$2:$F$293=C$24)*(COUNTIF(Themen!$K$5:$K$8,Drucksachen!$E$2:$E$293)>0)) | D28: =SUMPRODUCT(ISNUMBER(SEARCH($A28,Drucksachen!$I$2:$I$293))*(Drucksachen!$F$2:$F$293=D$24)*(COUNTIF(Themen!$K$5:$K$8,Drucksachen!$E$2:$E$293)>0)) | E28: =SUMPRODUCT(ISNUMBER(SEARCH($A28,Drucksachen!$I$2:$I$293))*(Drucksachen!$F$2:$F$293=E$24)*(COUNTIF(Themen!$K$5:$K$8,Drucksachen!$E$2:$E$293)>0)) | F28: =SUMPRODUCT(ISNUMBER(SEARCH($A28,Drucksachen!$I$2:$I$293))*(Drucksachen!$F$2:$F$293=F$24)*(COUNTIF(Themen!$K$5:$K$8,Drucksachen!$E$2:$E$293)>0)) | G28: =SUM(B28:F28) | H28: =IF(G28=0,"",INDEX($B$24:$F$24,MATCH(MAX(B28:F28),B28:F28,0)))
A29: Konzernstruktur/DB AG | B29: =SUMPRODUCT(ISNUMBER(SEARCH($A29,Drucksachen!$I$2:$I$293))*(Drucksachen!$F$2:$F$293=B$24)*(COUNTIF(Themen!$K$5:$K$8,Drucksachen!$E$2:$E$293)>0)) | C29: =SUMPRODUCT(ISNUMBER(SEARCH($A29,Drucksachen!$I$2:$I$293))*(Drucksachen!$F$2:$F$293=C$24)*(COUNTIF(Themen!$K$5:$K$8,Drucksachen!$E$2:$E$293)>0)) | D29: =SUMPRODUCT(ISNUMBER(SEARCH($A29,Drucksachen!$I$2:$I$293))*(Drucksachen!$F$2:$F$293=D$24)*(COUNTIF(Themen!$K$5:$K$8,Drucksachen!$E$2:$E$293)>0)) | E29: =SUMPRODUCT(ISNUMBER(SEARCH($A29,Drucksachen!$I$2:$I$293))*(Drucksachen!$F$2:$F$293=E$24)*(COUNTIF(Themen!$K$5:$K$8,Drucksachen!$E$2:$E$293)>0)) | F29: =SUMPRODUCT(ISNUMBER(SEARCH($A29,Drucksachen!$I$2:$I$293))*(Drucksachen!$F$2:$F$293=F$24)*(COUNTIF(Themen!$K$5:$K$8,Drucksachen!$E$2:$E$293)>0)) | G29: =SUM(B29:F29) | H29: =IF(G29=0,"",INDEX($B$24:$F$24,MATCH(MAX(B29:F29),B29:F29,0)))
A30: Sicherheit | B30: =SUMPRODUCT(ISNUMBER(SEARCH($A30,Drucksachen!$I$2:$I$293))*(Drucksachen!$F$2:$F$293=B$24)*(COUNTIF(Themen!$K$5:$K$8,Drucksachen!$E$2:$E$293)>0)) | C30: =SUMPRODUCT(ISNUMBER(SEARCH($A30,Drucksachen!$I$2:$I$293))*(Drucksachen!$F$2:$F$293=C$24)*(COUNTIF(Themen!$K$5:$K$8,Drucksachen!$E$2:$E$293)>0)) | D30: =SUMPRODUCT(ISNUMBER(SEARCH($A30,Drucksachen!$I$2:$I$293))*(Drucksachen!$F$2:$F$293=D$24)*(COUNTIF(Themen!$K$5:$K$8,Drucksachen!$E$2:$E$293)>0)) | E30: =SUMPRODUCT(ISNUMBER(SEARCH($A30,Drucksachen!$I$2:$I$293))*(Drucksachen!$F$2:$F$293=E$24)*(COUNTIF(Themen!$K$5:$K$8,Drucksachen!$E$2:$E$293)>0)) | F30: =SUMPRODUCT(ISNUMBER(SEARCH($A30,Drucksachen!$I$2:$I$293))*(Drucksachen!$F$2:$F$293=F$24)*(COUNTIF(Themen!$K$5:$K$8,Drucksachen!$E$2:$E$293)>0)) | G30: =SUM(B30:F30) | H30: =IF(G30=0,"",INDEX($B$24:$F$24,MATCH(MAX(B30:F30),B30:F30,0)))
A31: Finanzierung | B31: =SUMPRODUCT(ISNUMBER(SEARCH($A31,Drucksachen!$I$2:$I$293))*(Drucksachen!$F$2:$F$293=B$24)*(COUNTIF(Themen!$K$5:$K$8,Drucksachen!$E$2:$E$293)>0)) | C31: =SUMPRODUCT(ISNUMBER(SEARCH($A31,Drucksachen!$I$2:$I$293))*(Drucksachen!$F$2:$F$293=C$24)*(COUNTIF(Themen!$K$5:$K$8,Drucksachen!$E$2:$E$293)>0)) | D31: =SUMPRODUCT(ISNUMBER(SEARCH($A31,Drucksachen!$I$2:$I$293))*(Drucksachen!$F$2:$F$293=D$24)*(COUNTIF(Themen!$K$5:$K$8,Drucksachen!$E$2:$E$293)>0)) | E31: =SUMPRODUCT(ISNUMBER(SEARCH($A31,Drucksachen!$I$2:$I$293))*(Drucksachen!$F$2:$F$293=E$24)*(COUNTIF(Themen!$K$5:$K$8,Drucksachen!$E$2:$E$293)>0)) | F31: =SUMPRODUCT(ISNUMBER(SEARCH($A31,Drucksachen!$I$2:$I$293))*(Drucksachen!$F$2:$F$293=F$24)*(COUNTIF(Themen!$K$5:$K$8,Drucksachen!$E$2:$E$293)>0)) | G31: =SUM(B31:F31) | H31: =IF(G31=0,"",INDEX($B$24:$F$24,MATCH(MAX(B31:F31),B31:F31,0)))
A32: Puenktlichkeit/Qualitaet | B32: =SUMPRODUCT(ISNUMBER(SEARCH($A32,Drucksachen!$I$2:$I$293))*(Drucksachen!$F$2:$F$293=B$24)*(COUNTIF(Themen!$K$5:$K$8,Drucksachen!$E$2:$E$293)>0)) | C32: =SUMPRODUCT(ISNUMBER(SEARCH($A32,Drucksachen!$I$2:$I$293))*(Drucksachen!$F$2:$F$293=C$24)*(COUNTIF(Themen!$K$5:$K$8,Drucksachen!$E$2:$E$293)>0)) | D32: =SUMPRODUCT(ISNUMBER(SEARCH($A32,Drucksachen!$I$2:$I$293))*(Drucksachen!$F$2:$F$293=D$24)*(COUNTIF(Themen!$K$5:$K$8,Drucksachen!$E$2:$E$293)>0)) | E32: =SUMPRODUCT(ISNUMBER(SEARCH($A32,Drucksachen!$I$2:$I$293))*(Drucksachen!$F$2:$F$293=E$24)*(COUNTIF(Themen!$K$5:$K$8,Drucksachen!$E$2:$E$293)>0)) | F32: =SUMPRODUCT(ISNUMBER(SEARCH($A32,Drucksachen!$I$2:$I$293))*(Drucksachen!$F$2:$F$293=F$24)*(COUNTIF(Themen!$K$5:$K$8,Drucksachen!$E$2:$E$293)>0)) | G32: =SUM(B32:F32) | H32: =IF(G32=0,"",INDEX($B$24:$F$24,MATCH(MAX(B32:F32),B32:F32,0)))
